#VRML_SIM R2019a utf8
WorldInfo {
}
Viewpoint {
  orientation -0.9465843569742055 0.30348532699818687 0.10897114952377727 0.6643245222177476
  position 0.8159597388969122 3.4546515910212805 4.8713094307301095
}
TexturedBackground {
}
TexturedBackgroundLight {
}
RectangleArena {
  translation 0 -0.12000000000000002 0
  floorSize 4 4
  floorTileSize 1 1
}
DEF kedi Robot {
  translation -1.2500000107012532 -0.02150893870008637 1.3099999996158602
  rotation -5.8642908336531095e-08 0.9999999999999983 8.076646741804479e-14 3.141592643999999
  children [
    DEF FL Transform {
      translation -0.125 -0.049999999999999996 -0.1
      children [
        HingeJoint {
          jointParameters HingeJointParameters {
            position 7.957737318159665e-11
          }
          device [
            RotationalMotor {
              name "front_left"
            }
          ]
          endPoint Solid {
            rotation 4.0863811112219076e-10 -4.0863934966851424e-10 1 1.570799693899574
            children [
              DEF wheel Shape {
                appearance Appearance {
                }
                geometry Cylinder {
                  height 0.049999999999999996
                  radius 0.05
                }
              }
            ]
            boundingObject USE wheel
            physics Physics {
            }
          }
        }
      ]
    }
    DEF FR Transform {
      translation 0.125 -0.049999999999999996 -0.1
      children [
        HingeJoint {
          jointParameters HingeJointParameters {
            position 6.524944264925872e-11
          }
          device [
            RotationalMotor {
              name "front_right"
            }
          ]
          endPoint Solid {
            rotation 3.155066726845784e-10 -3.155075976470719e-10 1 1.570799693899574
            children [
              DEF wheel Shape {
                appearance Appearance {
                }
                geometry Cylinder {
                  height 0.049999999999999996
                  radius 0.05
                }
              }
            ]
            name "solid(1)"
            boundingObject USE wheel
            physics Physics {
            }
          }
        }
      ]
    }
    DEF RL Transform {
      translation -0.125 -0.049999999999999996 0.1
      children [
        HingeJoint {
          jointParameters HingeJointParameters {
            position 6.525247906485026e-11
          }
          device [
            RotationalMotor {
              name "rear_left"
            }
          ]
          endPoint Solid {
            rotation 3.155285488350958e-10 -3.155294738712487e-10 1 1.570799693899574
            children [
              DEF wheel Shape {
                appearance Appearance {
                }
                geometry Cylinder {
                  height 0.049999999999999996
                  radius 0.05
                }
              }
            ]
            name "solid(2)"
            boundingObject USE wheel
            physics Physics {
            }
          }
        }
      ]
    }
    DEF RR Transform {
      translation 0.125 -0.049999999999999996 0.1
      children [
        HingeJoint {
          jointParameters HingeJointParameters {
            position 7.957311537402311e-11
          }
          device [
            RotationalMotor {
              name "rear_right"
            }
          ]
          endPoint Solid {
            rotation 4.0861292070445485e-10 -4.0861415916595924e-10 1 1.570799693899574
            children [
              DEF wheel Shape {
                appearance Appearance {
                }
                geometry Cylinder {
                  height 0.049999999999999996
                  radius 0.05
                }
              }
            ]
            name "solid(3)"
            boundingObject USE wheel
            physics Physics {
            }
          }
        }
      ]
    }
    DEF BODY Shape {
      appearance Appearance {
        material Material {
          diffuseColor 1 0.3333333333333333 0
        }
      }
      geometry Box {
        size 0.2 0.1 0.30000000000000004
      }
    }
  ]
  boundingObject USE BODY
  physics Physics {
  }
  controller "4wheel_diff_drive"
  supervisor TRUE
}
DEF COINS Group {
}
DEF COIN_HANDLER Robot {
  name "robot(3)"
  controller "coin_handler"
  supervisor TRUE
}
